Workbook
Name STOCKS: [1]AB8!$B$8:$B$257

Sheet AB5
A1: Wishing You A Peace, Joy & Prosperity !! | H1: ENTRY | I1: LOTS | K1: TGT 1 | L1: LOTS | N1: TGT 2 | O1: LOTS | Q1: TGT 3 | R1: LOTS | T1: TGT 4 | U1: LOTS | W1: TGT 5 | X1: LOTS | Z1: TGT 6 | AA1: LOTS
H2: SL AFTER ENTRY | K2: TR PROFIT AFTER TGT 1 | N2: TR PROFIT AFTER TGT 2 | Q2: TR PROFIT AFTER TGT 3 | T2: TR PROFIT AFTER TGT 4 | W2: TR PROFIT AFTER TGT 5 | Z2: TR PROFIT AFTER TGT 6
A4: A | B4: Sr. No. | D4: BULL / BULL CF | F4: BUY | G4: E & T
A5: A | B5: Strategy Code | G5: SL / TRP
B6: Unique Code
A7: B | F7: SELL | G7: E & T
A8: B | G8: SL / TRP
A9: C | B9: Segment
A10: D | B10: Symbol | D10: BEAR / BEAR CF | F10: BUY | G10: E & T
A11: D | B11: No. of TGT | G11: SL / TRP
B12: Stay Blessed !!!
A13: E | F13: SELL | G13: E & T
A14: E | G14: SL / TRP
B16: For Entry | D16: Gap Check | G16: Process | I16: Y / N | K16: Order Status | L16: Step 1 | P16: Order Placement Timings | R16: Time | T16: Rules For Gaps | W16: Data | X16: Buffer | Z16: + | - | AA16: Rules For Re Entry
A17: A | B17: ORPT | C17: RC. Time | D17: For Long Entry | G17: Check If | H17: HH > Long Entry | I17: No | K17: Entry Not Missed | L17: Place the Order at ORPT | P17: ORPT Time | T17: N.A. | W17: N.A. | X17: N.A. | AA17: Long Entry : Bull/ Bull CF :
A18: B | I18: Yes | K18: Entry Missed | L18: Recalcuate : Long Entry : Bull / Bull CF | P18: Wait Till Recalculation Time | T18: Max | U18: HH | Z18: + | AA18: CDHH
L19: Recalcuate : Long Entry : Bear / Bear CF | P19: Wait Till Recalculation Time | T19: Max | U19: HH | Z19: + | AA19: Long Entry : Bear/ Bear CF :
B20: For SL (Position = Open) | D20: For Short Entry | G20: Check If | H20: LL < Short Entry | I20: No | K20: Entry Not Missed | L20: Place the Order at ORPT | P20: ORPT Time | T20: N.A. | W20: N.A. | X20: N.A. | AA20: CDHH
A21: A | B21: ORPT | C21: RC. Time | I21: Yes | K21: Entry Missed | L21: Recalcuate : Short Entry : Bull / Bull CF | P21: Wait Till Recalculation Time | T21: Min | U21: LL | Z21: - | AA21: When Your Long Position is Exited
A22: B | L22: Recalcuate : Short Entry : Bear / Bear CF | P22: Wait Till Recalculation Time | T22: Min | U22: LL | Z22: - | AA22: This is Only Applicable for Same Day
B24: For TGT (Position = Open) | D24: Gap Check | G24: Process | I24: Y / N | K24: Status | L24: Step 1 | P24: Order Placement Timings | R24: Time | T24: Rules For Gaps | W24: Data | X24: Buffer | AA24: Rules For Re Entry
A25: A | B25: ORPT | C25: RC. Time | D25: For Long SL | G25: Check If | H25: LL < Long SL | I25: No | K25: FSL / TRP Not Missed | L25: Place the Order at ORPT | P25: ORPT Time | U25: N.A. | W25: N.A. | X25: N.A. | AA25: Short Entry : Bull/ Bull CF :
A26: B | I26: Yes | K26: FSL / TRP Missed | L26: Recalcuate : Long FSL / TRP : Bull / Bull CF | P26: Wait Till Recalculation Time | U26: LL | Z26: - | AA26: CDLL
B27: I Commit To Follow The Rules & Process | L27: Recalcuate : Long FSL / TRP : Bear / Bear CF | P27: Wait Till Recalculation Time | U27: LL | Z27: -
L28: Recalcuate : Short Entry : Bull / Bull CF | P28: Wait Till Recalculation Time | T28: Min | U28: LL | Z28: -
L29: Recalcuate : Short Entry : Bear / Bear CF | P29: Wait Till Recalculation Time | T29: Min | U29: LL | Z29: - | AA29: Short Entry : Bear/ Bear CF :
B30: By Asmita Patel. | D30: For Short SL | G30: Check If | H30: HH > Short SL | I30: No | K30: FSL / TRP Not Missed | L30: Place the Order at ORPT | P30: ORPT Time | T30: N.A. | W30: N.A. | X30: N.A. | AA30: CDLL
I31: Yes | K31: FSL / TRP Missed | L31: Recalcuate : Short FSL / TRP : Bull / Bull CF | P31: Wait Till Recalculation Time | U31: HH | X31: 0 | Z31: +
L32: Recalcuate : Short FSL / TRP : Bear / Bear CF | P32: Wait Till Recalculation Time | U32: HH | X32: 0 | Z32: +
L33: Recalcuate : Long Entry : Bull / Bull CF | P33: Wait Till Recalculation Time | T33: Max | U33: HH | Z33: + | AA33: When Your Short Position is Exited
L34: Recalcuate : Long Entry : Bear / Bear CF | P34: Wait Till Recalculation Time | T34: Max | U34: HH | Z34: + | AA34: This is Only Applicable for Same Day
B35: For Missed SL (Position = Open) | I35: For Long SL | T35: For Short SL
A36: A | B36: Check time | D36: Note: ( Optional ) | G36: Check If Close at | H36: < Long Original SL | I36: Yes | K36: Then Square Off The Position At CMP at | T36: Check If Close at | U36: > Short Original SL | W36: Then Square Off The Position At CMP at
G37: Check If Close at | H37: > Long Original SL | I37: Yes | K37: Then Continue the Position for Next Day And Calculate Stop Loss Price as per the Rules | T37: Check If Close at | U37: < Short Original SL | W37: Then Continue the Position for Next Day And Calculate Stop Loss Price as per the Rules
B39: EQUITY
A41: Wishing You A Peace, Joy & Prosperity !! | H41: ENTRY | I41: LOTS | K41: TGT 1 | L41: LOTS | N41: TGT 2 | O41: LOTS | Q41: TGT 3 | R41: LOTS | T41: TGT 4 | U41: LOTS | W41: TGT 5 | X41: LOTS | Z41: TGT 6 | AA41: LOTS
H42: SL AFTER ENTRY | K42: TR PROFIT AFTER TGT 1 | N42: TR PROFIT AFTER TGT 2 | Q42: TR PROFIT AFTER TGT 3 | T42: TR PROFIT AFTER TGT 4 | W42: TR PROFIT AFTER TGT 5 | Z42: TR PROFIT AFTER TGT 6
A44: A | B44: Sr. No. | D44: ATH | E44: Check All Time High Price Till Previous Month | F44: BUY | G44: E & T
A45: A | B45: Strategy Code | E45: Candle should Close Above All Time High | G45: SL / TRP | Z45: N.A.
B46: Unique Code
...
